<?xml version="1.0"?>
<robot name="spider_robot" xmlns:xacro="http://ros.org/wiki/xacro">

  <material name="grey"><color rgba="0.5 0.5 0.5 1"/></material>
  <material name="blue"><color rgba="0.2 0.2 0.8 1"/></material>

  <link name="base_link">
    <visual><geometry><box size="0.25 0.25 0.067"/></geometry><material name="grey"/></visual>
    <collision><geometry><box size="0.25 0.25 0.067"/></geometry></collision>
    <inertial><mass value="2.0"/><inertia ixx="0.011" ixy="0.0" ixz="0.0" iyy="0.011" iyz="0.0" izz="0.021"/></inertial>
  </link>

  <joint name="rotational_motor-1" type="revolute">
    <parent link="base_link"/><child link="armmotorlink-1"/><axis xyz="0 1 0"/>
    <limit effort="27" lower="-2.09" upper="2.09" velocity="5.45"/>
    <origin xyz="0.125 0.125 0.035" rpy="1.5708 0 0.7854"/>
  </joint>
  <link name="armmotorlink-1">
    <visual><origin xyz="0 0.042 0"/><geometry><cylinder radius="0.03" length="0.057"/></geometry><material name="blue"/></visual>
    <inertial><mass value="0.2"/><inertia ixx="0.0001" ixy="0.0" ixz="0.0" iyy="0.0001" iyz="0.0" izz="0.0001"/></inertial>
  </link>
  <joint name="armmotor-1" type="revolute">
    <parent link="armmotorlink-1"/><child link="kneemotorlink-1"/><axis xyz="0 0 1"/>
    <limit effort="27" lower="-1.4" upper="1.57" velocity="5.45"/><origin xyz="0 0.042 0" rpy="0 0 0"/>
  </joint>
  <link name="kneemotorlink-1">
    <visual><origin xyz="0.09 0.01 0" rpy="0 1.57 0"/><geometry><cylinder radius="0.02" length="0.11"/></geometry></visual>
    <visual><origin xyz="0.18 0 0"/><geometry><cylinder radius="0.03" length="0.057"/></geometry></visual>
    <inertial><mass value="0.3"/><inertia ixx="0.0005" ixy="0.0" ixz="0.0" iyy="0.0005" iyz="0.0" izz="0.0001"/></inertial>
  </link>
  <joint name="kneemotor-1" type="revolute">
    <parent link="kneemotorlink-1"/><child link="balllink-1"/><axis xyz="0 0 1"/>
    <limit effort="27" lower="-0.9" upper="2" velocity="5.45"/><origin xyz="0.18 0 0" rpy="0 0 0"/>
  </joint>
  <link name="balllink-1">
    <visual><origin xyz="0 -0.105 0" rpy="1.57 0 0"/><geometry><cylinder radius="0.015" length="0.14"/></geometry></visual>
    <inertial><mass value="0.1"/><inertia ixx="1e-4" ixy="0.0" ixz="0.0" iyy="1e-4" iyz="0.0" izz="1e-4"/></inertial>
  </link>

  <joint name="ankle_pitch-1" type="revolute">
    <parent link="balllink-1"/><child link="ankle_dummy-1"/>
    <origin xyz="0 -0.2 0" rpy="0 0 0"/>
    <axis xyz="0 0 1"/>
    <limit effort="5" lower="-0.52" upper="0.52" velocity="10"/>
    <dynamics damping="0.5" friction="0.01" spring_stiffness="15.0" spring_reference="0.0"/>
  </joint>
  <link name="ankle_dummy-1">
    <inertial><mass value="0.01"/><inertia ixx="1e-5" ixy="0.0" ixz="0.0" iyy="1e-5" iyz="0.0" izz="1e-5"/></inertial>
  </link>

  <joint name="ankle_roll-1" type="revolute">
    <parent link="ankle_dummy-1"/><child link="foot_pyramid-1"/>
    <origin xyz="0 0 0" rpy="0 0 0"/>
    <axis xyz="1 0 0"/>
    <limit effort="5" lower="-0.52" upper="0.52" velocity="10"/>
    <dynamics damping="0.5" friction="0.01" spring_stiffness="15.0" spring_reference="0.0"/>
  </joint>
  
  <link name="foot_pyramid-1">
    <visual>
      <origin xyz="0 -0.01 0" rpy="0 0 0"/>
      <geometry><box size="0.04 0.02 0.04"/></geometry>
      <material name="blue"/>
    </visual>
    <inertial><mass value="0.05"/><inertia ixx="1e-4" ixy="0.0" ixz="0.0" iyy="1e-4" iyz="0.0" izz="1e-4"/></inertial>
  </link>

  <joint name="foot_joint_1" type="fixed">
    <parent link="foot_pyramid-1"/><child link="foot_1"/>
    <origin xyz="0 -0.02 0" rpy="1.5708 0 0"/>
  </joint>
  <link name="foot_1"/>

  <joint name="rotational_motor-2" type="revolute">
    <parent link="base_link"/><child link="armmotorlink-2"/><axis xyz="0 1 0"/>
    <limit effort="27" lower="-2.09" upper="2.09" velocity="5.45"/><origin xyz="-0.125 0.125 0.035" rpy="1.5708 0 2.3562"/>
  </joint>
  <link name="armmotorlink-2">
    <visual><origin xyz="0 0.042 0"/><geometry><cylinder radius="0.03" length="0.057"/></geometry><material name="blue"/></visual>
    <inertial><mass value="0.2"/><inertia ixx="0.0001" ixy="0.0" ixz="0.0" iyy="0.0001" iyz="0.0" izz="0.0001"/></inertial>
  </link>
  <joint name="armmotor-2" type="revolute">
    <parent link="armmotorlink-2"/><child link="kneemotorlink-2"/><axis xyz="0 0 1"/>
    <limit effort="27" lower="-1.4" upper="1.57" velocity="5.45"/><origin xyz="0 0.042 0" rpy="0 0 0"/>
  </joint>
  <link name="kneemotorlink-2">
    <visual><origin xyz="0.09 0.01 0" rpy="0 1.57 0"/><geometry><cylinder radius="0.02" length="0.11"/></geometry></visual>
    <visual><origin xyz="0.18 0 0"/><geometry><cylinder radius="0.03" length="0.057"/></geometry></visual>
    <inertial><mass value="0.3"/><inertia ixx="0.0005" ixy="0.0" ixz="0.0" iyy="0.0005" iyz="0.0" izz="0.0001"/></inertial>
  </link>
  <joint name="kneemotor-2" type="revolute">
    <parent link="kneemotorlink-2"/><child link="balllink-2"/><axis xyz="0 0 1"/>
    <limit effort="27" lower="-0.9" upper="2" velocity="5.45"/><origin xyz="0.18 0 0" rpy="0 0 0"/>
  </joint>
  <link name="balllink-2">
    <visual><origin xyz="0 -0.105 0" rpy="1.57 0 0"/><geometry><cylinder radius="0.015" length="0.14"/></geometry></visual>
    <inertial><mass value="0.1"/><inertia ixx="1e-4" ixy="0.0" ixz="0.0" iyy="1e-4" iyz="0.0" izz="1e-4"/></inertial>
  </link>

  <joint name="ankle_pitch-2" type="revolute">
    <parent link="balllink-2"/><child link="ankle_dummy-2"/><origin xyz="0 -0.2 0" rpy="0 0 0"/><axis xyz="0 0 1"/>
    <limit effort="5" lower="-0.52" upper="0.52" velocity="10"/>
    <dynamics damping="0.5" friction="0.01" spring_stiffness="15.0" spring_reference="0.0"/>
  </joint>
  <link name="ankle_dummy-2"><inertial><mass value="0.01"/><inertia ixx="1e-5" ixy="0.0" ixz="0.0" iyy="1e-5" iyz="0.0" izz="1e-5"/></inertial></link>
  <joint name="ankle_roll-2" type="revolute">
    <parent link="ankle_dummy-2"/><child link="foot_pyramid-2"/><origin xyz="0 0 0" rpy="0 0 0"/><axis xyz="1 0 0"/>
    <limit effort="5" lower="-0.52" upper="0.52" velocity="10"/>
    <dynamics damping="0.5" friction="0.01" spring_stiffness="15.0" spring_reference="0.0"/>
  </joint>
  <link name="foot_pyramid-2">
    <visual><origin xyz="0 -0.01 0" rpy="0 0 0"/><geometry><box size="0.04 0.02 0.04"/></geometry><material name="blue"/></visual>
    <inertial><mass value="0.05"/><inertia ixx="1e-4" ixy="0.0" ixz="0.0" iyy="1e-4" iyz="0.0" izz="1e-4"/></inertial>
  </link>
  <joint name="foot_joint_2" type="fixed">
    <parent link="foot_pyramid-2"/><child link="foot_2"/><origin xyz="0 -0.02 0" rpy="1.5708 0 0"/>
  </joint>
  <link name="foot_2"/>

  <joint name="rotational_motor-3" type="revolute">
    <parent link="base_link"/><child link="armmotorlink-3"/><axis xyz="0 1 0"/>
    <limit effort="27" lower="-2.09" upper="2.09" velocity="5.45"/><origin xyz="-0.125 -0.125 0.035" rpy="1.5708 0 -2.3562"/>
  </joint>
  <link name="armmotorlink-3">
    <visual><origin xyz="0 0.042 0"/><geometry><cylinder radius="0.03" length="0.057"/></geometry><material name="blue"/></visual>
    <inertial><mass value="0.2"/><inertia ixx="0.0001" ixy="0.0" ixz="0.0" iyy="0.0001" iyz="0.0" izz="0.0001"/></inertial>
  </link>
  <joint name="armmotor-3" type="revolute">
    <parent link="armmotorlink-3"/><child link="kneemotorlink-3"/><axis xyz="0 0 1"/>
    <limit effort="27" lower="-1.4" upper="1.57" velocity="5.45"/><origin xyz="0 0.042 0" rpy="0 0 0"/>
  </joint>
  <link name="kneemotorlink-3">
    <visual><origin xyz="0.09 0.01 0" rpy="0 1.57 0"/><geometry><cylinder radius="0.02" length="0.11"/></geometry></visual>
    <visual><origin xyz="0.18 0 0"/><geometry><cylinder radius="0.03" length="0.057"/></geometry></visual>
    <inertial><mass value="0.3"/><inertia ixx="0.0005" ixy="0.0" ixz="0.0" iyy="0.0005" iyz="0.0" izz="0.0001"/></inertial>
  </link>
  <joint name="kneemotor-3" type="revolute">
    <parent link="kneemotorlink-3"/><child link="balllink-3"/><axis xyz="0 0 1"/>
    <limit effort="27" lower="-0.9" upper="2" velocity="5.45"/><origin xyz="0.18 0 0" rpy="0 0 0"/>
  </joint>
  <link name="balllink-3">
    <visual><origin xyz="0 -0.105 0" rpy="1.57 0 0"/><geometry><cylinder radius="0.015" length="0.14"/></geometry></visual>
    <inertial><mass value="0.1"/><inertia ixx="1e-4" ixy="0.0" ixz="0.0" iyy="1e-4" iyz="0.0" izz="1e-4"/></inertial>
  </link>

  <joint name="ankle_pitch-3" type="revolute">
    <parent link="balllink-3"/><child link="ankle_dummy-3"/><origin xyz="0 -0.2 0" rpy="0 0 0"/><axis xyz="0 0 1"/>
    <limit effort="5" lower="-0.52" upper="0.52" velocity="10"/>
    <dynamics damping="0.5" friction="0.01" spring_stiffness="15.0" spring_reference="0.0"/>
  </joint>
  <link name="ankle_dummy-3"><inertial><mass value="0.01"/><inertia ixx="1e-5" ixy="0.0" ixz="0.0" iyy="1e-5" iyz="0.0" izz="1e-5"/></inertial></link>
  <joint name="ankle_roll-3" type="revolute">
    <parent link="ankle_dummy-3"/><child link="foot_pyramid-3"/><origin xyz="0 0 0" rpy="0 0 0"/><axis xyz="1 0 0"/>
    <limit effort="5" lower="-0.52" upper="0.52" velocity="10"/>
    <dynamics damping="0.5" friction="0.01" spring_stiffness="15.0" spring_reference="0.0"/>
  </joint>
  <link name="foot_pyramid-3">
    <visual><origin xyz="0 -0.01 0" rpy="0 0 0"/><geometry><box size="0.04 0.02 0.04"/></geometry><material name="blue"/></visual>
    <inertial><mass value="0.05"/><inertia ixx="1e-4" ixy="0.0" ixz="0.0" iyy="1e-4" iyz="0.0" izz="1e-4"/></inertial>
  </link>
  <joint name="foot_joint_3" type="fixed">
    <parent link="foot_pyramid-3"/><child link="foot_3"/><origin xyz="0 -0.02 0" rpy="1.5708 0 0"/>
  </joint>
  <link name="foot_3"/>

  <joint name="rotational_motor-4" type="revolute">
    <parent link="base_link"/><child link="armmotorlink-4"/><axis xyz="0 1 0"/>
    <limit effort="27" lower="-2.09" upper="2.09" velocity="5.45"/><origin xyz="0.125 -0.125 0.035" rpy="1.5708 0 -0.7854"/>
  </joint>
  <link name="armmotorlink-4">
    <visual><origin xyz="0 0.042 0"/><geometry><cylinder radius="0.03" length="0.057"/></geometry><material name="blue"/></visual>
    <inertial><mass value="0.2"/><inertia ixx="0.0001" ixy="0.0" ixz="0.0" iyy="0.0001" iyz="0.0" izz="0.0001"/></inertial>
  </link>
  <joint name="armmotor-4" type="revolute">
    <parent link="armmotorlink-4"/><child link="kneemotorlink-4"/><axis xyz="0 0 1"/>
    <limit effort="27" lower="-1.4" upper="1.57" velocity="5.45"/><origin xyz="0 0.042 0" rpy="0 0 0"/>
  </joint>
  <link name="kneemotorlink-4">
    <visual><origin xyz="0.09 0.01 0" rpy="0 1.57 0"/><geometry><cylinder radius="0.02" length="0.11"/></geometry></visual>
    <visual><origin xyz="0.18 0 0"/><geometry><cylinder radius="0.03" length="0.057"/></geometry></visual>
    <inertial><mass value="0.3"/><inertia ixx="0.0005" ixy="0.0" ixz="0.0" iyy="0.0005" iyz="0.0" izz="0.0001"/></inertial>
  </link>
  <joint name="kneemotor-4" type="revolute">
    <parent link="kneemotorlink-4"/><child link="balllink-4"/><axis xyz="0 0 1"/>
    <limit effort="27" lower="-0.9" upper="2" velocity="5.45"/><origin xyz="0.18 0 0" rpy="0 0 0"/>
  </joint>
  <link name="balllink-4">
    <visual><origin xyz="0 -0.105 0" rpy="1.57 0 0"/><geometry><cylinder radius="0.015" length="0.14"/></geometry></visual>
    <inertial><mass value="0.1"/><inertia ixx="1e-4" ixy="0.0" ixz="0.0" iyy="1e-4" iyz="0.0" izz="1e-4"/></inertial>
  </link>

  <joint name="ankle_pitch-4" type="revolute">
    <parent link="balllink-4"/><child link="ankle_dummy-4"/><origin xyz="0 -0.2 0" rpy="0 0 0"/><axis xyz="0 0 1"/>
    <limit effort="5" lower="-0.52" upper="0.52" velocity="10"/>
    <dynamics damping="0.5" friction="0.01" spring_stiffness="15.0" spring_reference="0.0"/>
  </joint>
  <link name="ankle_dummy-4"><inertial><mass value="0.01"/><inertia ixx="1e-5" ixy="0.0" ixz="0.0" iyy="1e-5" iyz="0.0" izz="1e-5"/></inertial></link>
  <joint name="ankle_roll-4" type="revolute">
    <parent link="ankle_dummy-4"/><child link="foot_pyramid-4"/><origin xyz="0 0 0" rpy="0 0 0"/><axis xyz="1 0 0"/>
    <limit effort="5" lower="-0.52" upper="0.52" velocity="10"/>
    <dynamics damping="0.5" friction="0.01" spring_stiffness="15.0" spring_reference="0.0"/>
  </joint>
  <link name="foot_pyramid-4">
    <visual><origin xyz="0 -0.01 0" rpy="0 0 0"/><geometry><box size="0.04 0.02 0.04"/></geometry><material name="blue"/></visual>
    <inertial><mass value="0.05"/><inertia ixx="1e-4" ixy="0.0" ixz="0.0" iyy="1e-4" iyz="0.0" izz="1e-4"/></inertial>
  </link>
  <joint name="foot_joint_4" type="fixed">
    <parent link="foot_pyramid-4"/><child link="foot_4"/><origin xyz="0 -0.02 0" rpy="1.5708 0 0"/>
  </joint>
  <link name="foot_4"/>

</robot>
